<?xml version='1.0'?>

<robot name="automobile_bot" xmlns:xacro="http://www.ros.org/wiki/xacro">
  <xacro:include filename="$(find automobile_bot)/urdf/automobile_bot.gazebo" />
  <link name="robot_footprint"></link>

  <joint name="robot_footprint_joint" type="fixed">
    <origin xyz="0 0 0" rpy="0 0 0" />
    <parent link="robot_footprint"/>
    <child link="chassis" />
  </joint>

<gazebo reference = "chassis">
      <material>Gazebo/DarkGrey</material>
</gazebo>

<gazebo reference = "front_left_wheel">
      <material>Gazebo/FlatBlack</material>
</gazebo>

<gazebo reference = "front_right_wheel">
      <material>Gazebo/FlatBlack</material>
</gazebo>

<gazebo reference = "rear_left_wheel">
      <material>Gazebo/FlatBlack</material>
</gazebo>

<gazebo reference = "rear_right_wheel">
      <material>Gazebo/FlatBlack</material>
</gazebo>

<gazebo reference = "camera">
      <material>Gazebo/Green</material>
</gazebo>

  <link name='chassis'>
    <pose>0 0 0.1 0 0 0</pose>

    <inertial>
      <mass value="20.0"/>
      <origin xyz="0.0 0 0" rpy=" 0 0 0"/>
      <inertia
          ixx="0.1" ixy="0" ixz="0"
          iyy="0.1" iyz="0"
          izz="0.1"
      />
    </inertial>

    <collision name='chassis_collision'>
      <origin xyz="0 0 0" rpy=" 0 0 0"/> 
      <geometry>
        <box size="1. .3 .1"/>
      </geometry>    
    </collision>

    <visual name='chassis_visual'>
      <origin xyz="0 0 0" rpy=" 0 0 0"/>
      <geometry>
        <box size="1. .3 .1"/>
      </geometry>
    </visual>

    <collision>
      <origin xyz="-0.05 0 0.05" rpy=" 0 0 0"/>
      <geometry>
        <box size="0.8 .25 .15"/>
      </geometry>
    </collision>

    <visual>
      <origin xyz="-0.05 0 0.05" rpy=" 0 0 0"/>
      <geometry>
        <box size="0.8 .25 .15"/>
      </geometry>
    </visual>

    <collision>
      <origin xyz="0.425 0.0725 0.05" rpy=" 0 0 0"/>
      <geometry>
        <box size="0.15 .05 .1"/>
      </geometry>
      <material name="">
        <color rgba="1.0 0.0 0.0 1.0"/>
      </material>
    </collision>

    <visual>
      <origin xyz="0.425 0.0725 0.05" rpy=" 0 0 0"/>
      <geometry>
        <box size="0.15 .05 .1"/>
      </geometry>
    </visual>

    <collision>
      <origin xyz="0.425 -0.0725 0.05" rpy=" 0 0 0"/>
      <geometry>
        <box size="0.15 .05 .1"/>
      </geometry>
    </collision>

    <visual>
      <origin xyz="0.425 -0.0725 0.05" rpy=" 0 0 0"/>
      <geometry>
        <box size="0.15 .05 .1"/>
      </geometry>
    </visual>

    <collision>
      <origin xyz="-0.3 0 -0.05" rpy=" 0 0 0"/>
      <geometry>
        <sphere radius="0.0499"/>
      </geometry>
        <surface>
        <friction>
          <ode>
            <mu>0.1</mu>
            <mu2>0.1</mu2>
            <slip1>1.0</slip1>
            <slip2>1.0</slip2>
          </ode>
        </friction>
        </surface> 
    </collision>

    <visual>
      <origin xyz="-0.3 0 -0.05" rpy=" 0 0 0"/>
      <geometry>
        <sphere radius="0.05"/>
      </geometry>
    </visual>

    <collision>
      <origin xyz="0 0 -0.05" rpy=" 0 0 0"/>
      <geometry>
        <sphere radius="0.0499"/>
      </geometry>
        <surface>
        <friction>
          <ode>
            <mu>0.1</mu>
            <mu2>0.1</mu2>
            <slip1>1.0</slip1>
            <slip2>1.0</slip2>
          </ode>
        </friction>
        </surface> 
    </collision>

    <visual>
      <origin xyz="0 0 -0.05" rpy=" 0 0 0"/>
      <geometry>
        <sphere radius="0.05"/>
      </geometry>
    </visual>

    <collision>
      <origin xyz="0.3 0 -0.05" rpy=" 0 0 0"/>
      <geometry>
        <sphere radius="0.0499"/>
      </geometry>
        <surface>
        <friction>
          <ode>
            <mu>0.1</mu>
            <mu2>0.1</mu2>
            <slip1>1.0</slip1>
            <slip2>1.0</slip2>
          </ode>
        </friction>
        </surface> 
    </collision>

    <visual>
      <origin xyz="0.3 0 -0.05" rpy=" 0 0 0"/>
      <geometry>
        <sphere radius="0.05"/>
      </geometry>
    </visual>
  </link>

 <link name="front_left_wheel">
    <inertial>
      <mass value="5.0"/>
      <origin xyz="0.0 0 0" rpy="0 1.5707 1.5707"/>
      <inertia
          ixx="0.1" ixy="0" ixz="0"
          iyy="0.1" iyz="0"
          izz="0.1"
      />
    </inertial>
    <visual name='front_left_wheel_visual'>
      <origin xyz="0 0 0" rpy="0 1.5707 1.5707"/>
      <geometry>
        <cylinder radius="0.15" length="0.15"/>
      </geometry>      
    </visual>

    <collision name='front_left_wheel_collision'>
      <origin xyz="0 0 0" rpy="0 1.5707 1.5707" />
      <geometry>
        <cylinder radius="0.15" length="0.15"/>
      </geometry>

      <surface>
        <friction>
          <ode>
            <mu>0.1</mu>
            <mu2>0.1</mu2>
            <slip1>1.0</slip1>
            <slip2>1.0</slip2>
          </ode>
        </friction>
        <contact>
          <ode>
            <kp>1000000.0</kp>
            <kd>100.0</kd>
            <minDepth>0.00</minDepth>
          </ode>
        </contact>
      </surface>
    </collision>
  </link>

  <joint type="continuous" name="front_left_wheel_hinge">
    <origin xyz="0.25 0.225 0" rpy="0 0 0"/>
    <child link="front_left_wheel"/>
    <parent link="chassis"/>
    <axis xyz="0 1 0" rpy="0 0 0"/>
    <limit effort="10000" velocity="1000"/>
    <dynamics damping="1.0" friction="1.0"/>
  </joint>

  <link name="front_right_wheel">
    <inertial>
      <mass value="5.0"/>
      <origin xyz="0.0 0 0" rpy="0 1.5707 1.5707"/>
      <inertia
          ixx="0.1" ixy="0" ixz="0"
          iyy="0.1" iyz="0"
          izz="0.1"
      />
    </inertial>
    <visual name='front_right_wheel_visual'>
      <origin xyz="0 0 0" rpy="0 1.5707 1.5707"/>
      <geometry>
        <cylinder radius="0.15" length="0.15"/>
      </geometry>
    </visual>
    <collision name='front_right_wheel_collision'>
      <origin xyz="0 0 0" rpy="0 1.5707 1.5707" />
      <geometry>
        <cylinder radius="0.15" length="0.15"/>
      </geometry>
      <surface>
        <friction>
          <ode>
            <mu>0.1</mu>
            <mu2>0.1</mu2>
            <slip1>1.0</slip1>
            <slip2>1.0</slip2>
          </ode>
        </friction>
        <contact>
          <ode>
            <kp>1000000.0</kp>
            <kd>100.0</kd>
            <minDepth>0.00</minDepth>
          </ode>
        </contact>
      </surface>
    </collision>
  </link>

  <joint type="continuous" name="front_right_wheel_hinge">
    <origin xyz="0.25 -0.225 0" rpy="0 0 0"/>
    <child link="front_right_wheel"/>
    <parent link="chassis"/>
    <axis xyz="0 1 0" rpy="0 0 0"/>
    <limit effort="10000" velocity="1000"/>
    <dynamics damping="1.0" friction="1.0"/>
  </joint>

 <link name="rear_left_wheel">
    <inertial>
      <mass value="5.0"/>
      <origin xyz="0.0 0 0" rpy="0 1.5707 1.5707"/>
      <inertia
          ixx="0.1" ixy="0" ixz="0"
          iyy="0.1" iyz="0"
          izz="0.1"
      />
    </inertial>
    <visual name='rear_left_wheel_visual'>
      <origin xyz="0 0 0" rpy="0 1.5707 1.5707"/>
      <geometry>
        <cylinder radius="0.15" length="0.15"/>
      </geometry>
    </visual>

    <collision name='rear_left_wheel_collision'>
      <origin xyz="0 0 0" rpy="0 1.5707 1.5707" />
      <geometry>
        <cylinder radius="0.15" length="0.15"/>
      </geometry>
      <surface>
        <friction>
          <ode>
            <mu>0.1</mu>
            <mu2>0.1</mu2>
            <slip1>1.0</slip1>
            <slip2>1.0</slip2>
          </ode>
        </friction>
        <contact>
          <ode>
            <kp>1000000.0</kp>
            <kd>100.0</kd>
            <minDepth>0.00</minDepth>
          </ode>
        </contact>
      </surface>
    </collision>
  </link>

  <joint type="continuous" name="rear_left_wheel_hinge">
    <origin xyz="-0.25 0.225 0" rpy="0 0 0"/>
    <child link="rear_left_wheel"/>
    <parent link="chassis"/>
    <axis xyz="0 1 0" rpy="0 0 0"/>
    <limit effort="10000" velocity="1000"/>
    <dynamics damping="1.0" friction="1.0"/>
  </joint>

  <link name="rear_right_wheel">
    <inertial>
      <mass value="5.0"/>
      <origin xyz="0.0 0 0" rpy="0 1.5707 1.5707"/>
      <inertia
          ixx="0.1" ixy="0" ixz="0"
          iyy="0.1" iyz="0"
          izz="0.1"
      />
    </inertial>
    <visual name='rear_right_wheel_visual'>
      <origin xyz="0 0 0" rpy="0 1.5707 1.5707"/>
      <geometry>
        <cylinder radius="0.15" length="0.15"/>
      </geometry>
    </visual>
    <collision name='rear_right_wheel_collision'>
      <origin xyz="0 0 0" rpy="0 1.5707 1.5707" />
      <geometry>
        <cylinder radius="0.15" length="0.15"/>
      </geometry>
      <surface>
        <friction>
          <ode>
            <mu>0.1</mu>
            <mu2>0.1</mu2>
            <slip1>1.0</slip1>
            <slip2>1.0</slip2>
          </ode>
        </friction>
        <contact>
          <ode>
            <kp>1000000.0</kp>
            <kd>100.0</kd>
            <minDepth>0.00</minDepth>
          </ode>
        </contact>
      </surface>
    </collision>
  </link>

  <joint type="continuous" name="rear_right_wheel_hinge">
    <origin xyz="-0.25 -0.225 0" rpy="0 0 0"/>
    <child link="rear_right_wheel"/>
    <parent link="chassis"/>
    <axis xyz="0 1 0" rpy="0 0 0"/>
    <limit effort="10000" velocity="1000"/>
    <dynamics damping="1.0" friction="1.0"/>
  </joint>

  <link name="camera">
    <inertial>
      <mass value="0.1"/>
      <origin xyz="0 0 0" rpy="0 0 0"/>
      <inertia
          ixx="1e-6" ixy="0" ixz="0"
          iyy="1e-6" iyz="0"
          izz="1e-6"
      />
    </inertial>
    <visual name='camera_visual'>
      <origin xyz="0 0 0" rpy="0 0 0"/>
      <geometry>
        <box size="0.05 0.05 0.05"/>
      </geometry>
    </visual>
    <collision name='camera_collision'>
      <origin xyz="0 0 0" rpy="0 0 0" />
      <geometry>
        <box size="0.05 0.05 0.05"/>
      </geometry>
    </collision>
  </link>

  <joint type="fixed" name="camera_joint">
    <origin xyz="0.5 0 0" rpy="0 0 0"/>
    <child link="camera"/>
    <parent link="chassis"/>
    <axis xyz="0 1 0" rpy="0 0 0"/>
  </joint>

  <link name="hokuyo">
    <inertial>
      <mass value="1e-5"/>
      <origin xyz="0 0 0" rpy="0 0 0"/>
      <inertia
          ixx="1e-6" ixy="0" ixz="0"
          iyy="1e-6" iyz="0"
          izz="1e-6"
      />
    </inertial>
    <visual name='hokuyo_visual'>
      <origin xyz="0 0 0" rpy="0 0 0"/>
      <geometry>
        <mesh filename="package://automobile_bot/meshes/hokuyo.dae"/>
      </geometry>
    </visual>
    <collision name='hokuyo_collision'>
      <origin xyz="0 0 0" rpy="0 0 0" />
      <geometry>
        <box size="0.1 0.1 0.1"/>
      </geometry>
    </collision>
  </link>

  <joint type="fixed" name="hokuyo_joint">
    <origin xyz="0.25 0 0.15" rpy="0 0 0"/>
    <child link="hokuyo"/>
    <parent link="chassis"/>
    <axis xyz="0 1 0" rpy="0 0 0"/>
  </joint>

</robot>
